#VRML_SIM R2022a utf8
WorldInfo {
}
Viewpoint {
  orientation -0.16290331122944582 0.07889837311050155 0.9834823627859314 2.2525498983798276
  position 4.913720181364097 -2.2972690365274184 1.1408730585813869
}
TexturedBackground {
}
TexturedBackgroundLight {
}
RectangleArena {
  floorSize 8 8
}
DEF cube_runner Robot {
  translation 3 0 0.05
  rotation 0 1 0 0
  children [
    DEF right_hinge HingeJoint {
      jointParameters HingeJointParameters {
        axis 0 1 0
      }
      device [
        DEF right_motor RotationalMotor {
          name "right_motor"
        }
      ]
      endPoint Solid {
        translation 0 0.1 0
        rotation 0 1 0 0
        children [
          DEF foot Shape {
            appearance PBRAppearance {
              baseColor 0.192203 1 0.994965
              metalness 0
            }
            geometry Box {
              size 0.3 0.1 0.02
            }
          }
        ]
        name "right_block"
        boundingObject USE foot
        physics DEF foot_physics Physics {
        }
      }
    }
    DEF left_hinge HingeJoint {
      jointParameters HingeJointParameters {
        axis 0 1 0
      }
      device [
        DEF left_motor RotationalMotor {
          name "left_motor"
        }
      ]
      endPoint Solid {
        translation 0 -0.1 0
        rotation 0 1 0 0
        children [
          DEF foot Shape {
            appearance PBRAppearance {
              baseColor 0.192203 1 0.994965
              metalness 0
            }
            geometry Box {
              size 0.3 0.1 0.02
            }
          }
        ]
        boundingObject USE foot
        physics DEF foot_physics Physics {
        }
      }
    }
    DEF body Shape {
      appearance PBRAppearance {
        baseColor 0.521447 0 0.977783
        metalness 0
      }
      geometry Box {
        size 0.1 0.1 0.1
      }
    }
  ]
  name "cube_runner"
  boundingObject USE body
  physics Physics {
  }
  controller "cube_runner_controller"
}
