#VRML_SIM R2022a utf8
WorldInfo {
}
Viewpoint {
  orientation -0.24409041378810573 0.14171715215349895 0.9593415026372273 2.125221139604997
  position 3.402974603250735 -0.7067520342613839 0.5112526359308137
}
TexturedBackground {
}
TexturedBackgroundLight {
}
RectangleArena {
  floorSize 8 8
}
DEF cube_runner Robot {
  translation 3 0 0.05
  rotation 0 1 0 0
  children [
    DEF gps GPS {
      children [
        Solid {
          translation 0 0 0.05
          children [
            Shape {
              appearance PBRAppearance {
              }
              geometry Cylinder {
                height 0.01
                radius 0.01
              }
            }
          ]
        }
      ]
    }
    DEF right_hinge HingeJoint {
      jointParameters HingeJointParameters {
        axis 0.2 1 0
      }
      device [
        DEF right_motor RotationalMotor {
          name "right_motor"
        }
      ]
      endPoint Solid {
        translation 0.03 0.1 0
        rotation 0.19611613513818404 0.9805806756909201 0 0
        children [
          DEF foot Shape {
            appearance PBRAppearance {
              baseColor 0.192203 1 0.994965
              metalness 0
            }
            geometry Box {
              size 0.2 0.1 0.02
            }
          }
        ]
        name "right_block"
        boundingObject USE foot
        physics DEF foot_physics Physics {
        }
      }
    }
    DEF left_hinge HingeJoint {
      jointParameters HingeJointParameters {
        axis 0.2 1 0
      }
      device [
        DEF left_motor RotationalMotor {
          name "left_motor"
        }
      ]
      endPoint Solid {
        translation -0.02 -0.1 0
        rotation 0.19611613513818404 0.9805806756909201 0 0
        children [
          DEF foot Shape {
            appearance PBRAppearance {
              baseColor 0.192203 1 0.994965
              metalness 0
            }
            geometry Box {
              size 0.2 0.1 0.02
            }
          }
        ]
        boundingObject USE foot
        physics DEF foot_physics Physics {
        }
      }
    }
    DEF body Shape {
      appearance PBRAppearance {
        baseColor 0.521447 0 0.977783
        metalness 0
      }
      geometry Box {
        size 0.1 0.1 0.1
      }
    }
  ]
  name "cube_runner"
  boundingObject USE body
  physics Physics {
  }
  controller "cube_runner_controller"
}
DEF supervisor Robot {
  name "supervisor"
  controller "supervisor_controller"
  supervisor TRUE
}
